ERROR 2025-09-28 06:35:07,646 decorators API call failed: start_session_view - "Attempt to overwrite 'message' in LogRecord"
ERROR 2025-09-28 06:35:07,646 decorators Unexpected error in API view start_session_view: "Attempt to overwrite 'message' in LogRecord"
Traceback (most recent call last):
  File "/Volumes/personal/programmingFolders/saas/20-20-20/mysite/decorators.py", line 49, in wrapper
    result = view_func(request, *args, **kwargs)
             ^^^^^^^^^^^^^^^^^^^^^^^^^^^^^^^^^^^
  File "/Volumes/personal/programmingFolders/saas/20-20-20/mysite/decorators.py", line 347, in wrapper
    response = view_func(request, *args, **kwargs)
               ^^^^^^^^^^^^^^^^^^^^^^^^^^^^^^^^^^^
  File "/Volumes/personal/programmingFolders/saas/20-20-20/mysite/decorators.py", line 109, in wrapper
    raise UserNotAuthenticatedError(
          ^^^^^^^^^^^^^^^^^^^^^^^^^^
  File "/Volumes/personal/programmingFolders/saas/20-20-20/mysite/exceptions.py", line 59, in __init__
    self._log_error()
  File "/Volumes/personal/programmingFolders/saas/20-20-20/mysite/exceptions.py", line 70, in _log_error
    logger.log(
  File "/Volumes/personal/conda_envs/webapp/lib/python3.11/logging/__init__.py", line 1559, in log
    self._log(level, msg, args, **kwargs)
  File "/Volumes/personal/conda_envs/webapp/lib/python3.11/logging/__init__.py", line 1632, in _log
    record = self.makeRecord(self.name, level, fn, lno, msg, args,
             ^^^^^^^^^^^^^^^^^^^^^^^^^^^^^^^^^^^^^^^^^^^^^^^^^^^^^
  File "/Volumes/personal/conda_envs/webapp/lib/python3.11/logging/__init__.py", line 1606, in makeRecord
    raise KeyError("Attempt to overwrite %r in LogRecord" % key)
KeyError: "Attempt to overwrite 'message' in LogRecord"
ERROR 2025-09-28 06:35:07,649 log Internal Server Error: /timer/start/
ERROR 2025-09-28 06:35:10,753 middleware Unexpected error: AxesBackendRequestParameterRequired: AxesBackend requires a request as an argument to authenticate
Traceback (most recent call last):
  File "/Volumes/personal/conda_envs/webapp/lib/python3.11/site-packages/django/core/handlers/base.py", line 197, in _get_response
    response = wrapped_callback(request, *callback_args, **callback_kwargs)
               ^^^^^^^^^^^^^^^^^^^^^^^^^^^^^^^^^^^^^^^^^^^^^^^^^^^^^^^^^^^^
  File "/Volumes/personal/conda_envs/webapp/lib/python3.11/site-packages/django/views/generic/base.py", line 104, in view
    return self.dispatch(request, *args, **kwargs)
           ^^^^^^^^^^^^^^^^^^^^^^^^^^^^^^^^^^^^^^^
  File "/Volumes/personal/conda_envs/webapp/lib/python3.11/site-packages/django/views/generic/base.py", line 143, in dispatch
    return handler(request, *args, **kwargs)
           ^^^^^^^^^^^^^^^^^^^^^^^^^^^^^^^^^
  File "/Volumes/personal/conda_envs/webapp/lib/python3.11/site-packages/django/views/generic/edit.py", line 184, in post
    return super().post(request, *args, **kwargs)
           ^^^^^^^^^^^^^^^^^^^^^^^^^^^^^^^^^^^^^^
  File "/Volumes/personal/conda_envs/webapp/lib/python3.11/site-packages/django/views/generic/edit.py", line 153, in post
    return self.form_valid(form)
           ^^^^^^^^^^^^^^^^^^^^^
  File "/Volumes/personal/programmingFolders/saas/20-20-20/accounts/views.py", line 40, in form_valid
    user = authenticate(username=email, password=raw_password)
           ^^^^^^^^^^^^^^^^^^^^^^^^^^^^^^^^^^^^^^^^^^^^^^^^^^^
  File "/Volumes/personal/conda_envs/webapp/lib/python3.11/site-packages/django/views/decorators/debug.py", line 42, in sensitive_variables_wrapper
    return func(*func_args, **func_kwargs)
           ^^^^^^^^^^^^^^^^^^^^^^^^^^^^^^^
  File "/Volumes/personal/conda_envs/webapp/lib/python3.11/site-packages/django/contrib/auth/__init__.py", line 77, in authenticate
    user = backend.authenticate(request, **credentials)
           ^^^^^^^^^^^^^^^^^^^^^^^^^^^^^^^^^^^^^^^^^^^^
  File "/Volumes/personal/conda_envs/webapp/lib/python3.11/site-packages/axes/helpers.py", line 614, in inner
    return func(*args, **kwargs)
           ^^^^^^^^^^^^^^^^^^^^^
  File "/Volumes/personal/conda_envs/webapp/lib/python3.11/site-packages/axes/backends.py", line 46, in authenticate
    raise AxesBackendRequestParameterRequired(
axes.exceptions.AxesBackendRequestParameterRequired: AxesBackend requires a request as an argument to authenticate
ERROR 2025-09-28 06:35:10,779 log Internal Server Error: /signup/
ERROR 2025-09-29 04:38:59,142 decorators API call failed: start_session_view - "Attempt to overwrite 'message' in LogRecord"
ERROR 2025-09-29 04:38:59,142 decorators Unexpected error in API view start_session_view: "Attempt to overwrite 'message' in LogRecord"
Traceback (most recent call last):
  File "/Volumes/personal/programmingFolders/saas/20-20-20/mysite/decorators.py", line 49, in wrapper
    result = view_func(request, *args, **kwargs)
             ^^^^^^^^^^^^^^^^^^^^^^^^^^^^^^^^^^^
  File "/Volumes/personal/programmingFolders/saas/20-20-20/mysite/decorators.py", line 347, in wrapper
    response = view_func(request, *args, **kwargs)
               ^^^^^^^^^^^^^^^^^^^^^^^^^^^^^^^^^^^
  File "/Volumes/personal/programmingFolders/saas/20-20-20/mysite/decorators.py", line 109, in wrapper
    raise UserNotAuthenticatedError(
          ^^^^^^^^^^^^^^^^^^^^^^^^^^
  File "/Volumes/personal/programmingFolders/saas/20-20-20/mysite/exceptions.py", line 59, in __init__
    self._log_error()
  File "/Volumes/personal/programmingFolders/saas/20-20-20/mysite/exceptions.py", line 70, in _log_error
    logger.log(
  File "/Volumes/personal/conda_envs/webapp/lib/python3.11/logging/__init__.py", line 1559, in log
    self._log(level, msg, args, **kwargs)
  File "/Volumes/personal/conda_envs/webapp/lib/python3.11/logging/__init__.py", line 1632, in _log
    record = self.makeRecord(self.name, level, fn, lno, msg, args,
             ^^^^^^^^^^^^^^^^^^^^^^^^^^^^^^^^^^^^^^^^^^^^^^^^^^^^^
  File "/Volumes/personal/conda_envs/webapp/lib/python3.11/logging/__init__.py", line 1606, in makeRecord
    raise KeyError("Attempt to overwrite %r in LogRecord" % key)
KeyError: "Attempt to overwrite 'message' in LogRecord"
ERROR 2025-09-29 04:38:59,145 log Internal Server Error: /timer/start/
ERROR 2025-09-29 04:39:01,641 middleware Unexpected error: AxesBackendRequestParameterRequired: AxesBackend requires a request as an argument to authenticate
Traceback (most recent call last):
  File "/Volumes/personal/conda_envs/webapp/lib/python3.11/site-packages/django/core/handlers/base.py", line 197, in _get_response
    response = wrapped_callback(request, *callback_args, **callback_kwargs)
               ^^^^^^^^^^^^^^^^^^^^^^^^^^^^^^^^^^^^^^^^^^^^^^^^^^^^^^^^^^^^
  File "/Volumes/personal/conda_envs/webapp/lib/python3.11/site-packages/django/views/generic/base.py", line 104, in view
    return self.dispatch(request, *args, **kwargs)
           ^^^^^^^^^^^^^^^^^^^^^^^^^^^^^^^^^^^^^^^
  File "/Volumes/personal/conda_envs/webapp/lib/python3.11/site-packages/django/views/generic/base.py", line 143, in dispatch
    return handler(request, *args, **kwargs)
           ^^^^^^^^^^^^^^^^^^^^^^^^^^^^^^^^^
  File "/Volumes/personal/conda_envs/webapp/lib/python3.11/site-packages/django/views/generic/edit.py", line 184, in post
    return super().post(request, *args, **kwargs)
           ^^^^^^^^^^^^^^^^^^^^^^^^^^^^^^^^^^^^^^
  File "/Volumes/personal/conda_envs/webapp/lib/python3.11/site-packages/django/views/generic/edit.py", line 153, in post
    return self.form_valid(form)
           ^^^^^^^^^^^^^^^^^^^^^
  File "/Volumes/personal/programmingFolders/saas/20-20-20/accounts/views.py", line 40, in form_valid
    user = authenticate(username=email, password=raw_password)
           ^^^^^^^^^^^^^^^^^^^^^^^^^^^^^^^^^^^^^^^^^^^^^^^^^^^
  File "/Volumes/personal/conda_envs/webapp/lib/python3.11/site-packages/django/views/decorators/debug.py", line 42, in sensitive_variables_wrapper
    return func(*func_args, **func_kwargs)
           ^^^^^^^^^^^^^^^^^^^^^^^^^^^^^^^
  File "/Volumes/personal/conda_envs/webapp/lib/python3.11/site-packages/django/contrib/auth/__init__.py", line 77, in authenticate
    user = backend.authenticate(request, **credentials)
           ^^^^^^^^^^^^^^^^^^^^^^^^^^^^^^^^^^^^^^^^^^^^
  File "/Volumes/personal/conda_envs/webapp/lib/python3.11/site-packages/axes/helpers.py", line 614, in inner
    return func(*args, **kwargs)
           ^^^^^^^^^^^^^^^^^^^^^
  File "/Volumes/personal/conda_envs/webapp/lib/python3.11/site-packages/axes/backends.py", line 46, in authenticate
    raise AxesBackendRequestParameterRequired(
axes.exceptions.AxesBackendRequestParameterRequired: AxesBackend requires a request as an argument to authenticate
ERROR 2025-09-29 04:39:01,647 log Internal Server Error: /signup/
